Workbook

Sheet シートの説明
B2: 東京都立豊島病院 | F2: 様用 AI電話準備シート
B4: このシートについて
B5: AI電話稼働開始までに決定・設定したい項目の一覧になります。
B6: 貴院内で検討いただき、各項目を回答ください。
B8: ▼シートマップ | E8: 回答タイミング | G8: 対応状況
B9: ①スタッフ招待リスト | E9: キックオフMTG前後 | F9: AI電話をご利用されるスタッフの皆様へDr.JOYアカウントのご招待をいたします。 | G9: FALSE
B10: ②（診療科or健診）ヒアリングシート | E10: キックオフMTG前後 | F10: Dr.JOY管理画面へ表示させる診療科・健診コース名と、患者様が発話される可能性のある類義語の確認をお願いします。 また、（C列：AI電話の対応可否）（AA列：転送の場合は転送先電話番号）の記載をお願いします。 | G10: FALSE
B11: ③運用ヒアリングシート | E11: キックオフMTG前後 | F11: AI電話の稼働時間や利用用途等、ご希望を記載お願いします。 | G11: FALSE
B12: ④よくある質問 | E12: 稼働後、 貴院で設定することも可能 | F12: 電話対応時によく受ける質問をAIに登録することで、AIが自動で回答をすることが可能です。 | G12: FALSE
B13: ⑤共有物リンク | E13: 不要 | F13: Dr.JOYから貴院への共有物に関するリンクをまとめております。
B15: ▼フォーム回答依頼 | E15: 回答タイミング
B16: 周知資料希望確認 | E16: キックオフMTG前後 | F16: 回答フォームより、ご希望をご回答ください。 https://docs.google.com/forms/d/e/1FAIpQLSez2CJrWTGCVOxZTQ3d9i2zAr3GbiDlvXNgYU4i0M-AdcLKFg/viewform | G16: FALSE
B18: ▼AI電話に関するマニュアルリンク
B19: 操作マニュアル（teachme） | E19: 不要 | F19: https://teachme.jp/7884/f/room0RfvU2rl/sf/177237?page=1&sortKey=title&sortOrder=asc&keywordKind=full_text
B20: 操作マニュアル（スライド） | E20: 不要 | F20: https://drive.google.com/file/d/1238F3fsOqXwnBED9KvFIf3aKheNcq0Q6/view?usp=sharing
B21: 操作動画 | E21: 不要 | F21: https://drive.google.com/drive/folders/1V4E9qxzSX1Yj27tcbwA2KEfvVLBMAQJw?usp=sharing
B22: 管理者(代表者)アカウントと一般アカウントの権限の違い | E22: 不要 | F22: https://drive.google.com/file/d/1Y3smOi9pbgsN-Mv_Hey_YPOsTR8nasu8/view?usp=sharing
B23: 周知活動に関して | E23: 不要 | F23: https://drive.google.com/file/d/1X1MuU2HRFGOIPcvoX1OZOPenwU7hIm7B/view?usp=sharing
B25: ▼AI電話以外のサービス
B26: SMS一斉連絡テンプレート | E26: 不要 | F26: https://drive.google.com/file/d/11LJvaVlS_ZbbN5Do4G7MqUbqu8vZoa5f/view?usp=sharing

Sheet ①スタッフ招待リスト
A1: Dr.JOY スタッフ一括招待テンプレート
A2: 対応依頼事項 AI電話をご利用されるスタッフの皆様の情報をご記載ください。一人1アカウントでの利用を推奨しておりますが、診療科ごとなど、複数人で同一アカウントをご利用することも可能です。 メールアドレスをお持ちでない方は、半角英数字8文字以上64文字以内で任意のIDをご指定下さい。 既にDr.JOYアカウントをお持ちの方も、AI電話の権限を付与するため、姓名(アカウント名)の記載をお願いします。
A4: 病院記入欄 | H4: Dr.JOY記入欄
A5: 姓 | B5: 名 | C5: せい | D5: めい | E5: 職業 | F5: ログインID（メールアドレス） | G5: 代表者 | H5: 招待メール送信 | I5: グループ招待 | J5: シナリオ 権限付与
A6: 16文字まで | B6: 16文字まで | C6: 16文字まで | D6: 16文字まで | E6: 選択して下さい | F6: 半角英数字8文字以上64文字以内 | G6: 代表者のみ「〇」を記載 代表者とは
A8: 例）若林 | B8: 太郎 | C8: わかばやし | D8: たろう | E8: 事務 | F8: sample@drjoy.jp | G8: 〇
A9: 例）医事科 | B9: ① | C9: いじか | D9: いち | E9: 事務 | F9: drjoy_denwa_01
A10: 宮川 | B10: 聡史 | C10: みやかわ | D10: さとし | E10: 事務 | F10: satoshi_miyakawa@tmhp.jp | H10: 済
A11: 山村 | B11: 恭一 | C11: やまむら | D11: きょういち | E11: 事務 | F11: kyouichi_1_yamamura@tmhp.jp | H11: 済
A12: 高木 | B12: 由紀子 | C12: たかぎ | D12: ゆきこ | E12: 事務 | F12: yukiko_takagi@tmhp.jp | H12: 済
A13: 移川 | B13: 恭代 | C13: うつしかわ | D13: やすよ | E13: 事務 | F13: yasuyo_utsushikawa@tmhp.jp | H13: 済
A14: 小林 | B14: 悠衣 | C14: こばやし | D14: ゆい | E14: 事務 | F14: yui_matsumura@tmhp.jp | H14: 済
A15: 岩尾 | B15: 真由美 | C15: いわお | D15: まゆみ | E15: 事務 | F15: mayumi_iwao@tmhp.jp | H15: 済
A16: 辻 | B16: 佑好 | C16: つじ | D16: ゆうこ | E16: 事務 | F16: yuko_tsuji@tmhp.jp | H16: 済
A17: 鹿内 | B17: 弘実 | C17: しかうち | D17: ひろみ | E17: 事務 | F17: hiromi_shikauchi@tmhp.jp | H17: 済
A18: 中井 | B18: 賢太 | C18: なかい | D18: けんた | E18: 事務 | F18: kenta_nakai@tmhp.jp | H18: 済
A19: 古賀 | B19: 大意 | C19: こが | D19: だいい | E19: 事務 | F19: daii_koga@tmhp.jp | G19: ○ | H19: 済

Sheet ②（選択）診療科ヒアリングシート
A1: 診療科ヒアリングシート | M1: ↑
M2: 類義語足りなければプラスを押す
A3: 対応依頼事項
A4: B列【登録診療科名】・・・貴院HPに記載のある診療科名を記載しております。Dr.JOY管理画面へ表示させる診療科名となるため、ご確認をお願いします。表示名を変える場合は、ご修正ください。
A5: D列以降【類義語】・・・B列の診療科名に対して、患者さんが発話される可能性のある別称を記載しております。類義語の追加がございましたら、他の診療科と重複しないよう追記をお願いいたします。
A6: C列・AA列・・・AI電話で内容を受け付けない診療科や、転送をする診療科があればC列に記載ください。また、転送の場合はAA列に転送先番号を記載ください。
D8: 2 | E8: 3 | F8: 4 | G8: 5 | H8: 6 | I8: 7 | J8: 8 | K8: 9 | L8: 10 | M8: 11
A9: No. | B9: 登録診療科名 (Dr.JOY管理画面へ表示する名称) | C9: AI電話対応可否 (〇可 / ×不可 / △転送) | D9: 類義語 | E9: 類義語 | F9: 類義語 | G9: 類義語 | H9: 類義語 | I9: 類義語 | J9: 類義語 | K9: 類義語 | L9: 類義語 | M9: 類義語 | N9: 類義語 | O9: 類義語 | P9: 類義語 | Q9: 類義語 | R9: 類義語 | S9: 類義語 | T9: 類義語 | U9: 類義語 | V9: 類義語 | W9: 類義語 | X9: 類義語 | Y9: 類義語 | Z9: 類義語 | AA9: 備考 (転送先電話番号)
A10: 例 | B10: 総合内科 | C10: 〇 | D10: ないか | E10: そうごう | F10: そうない | AA10: 0XX-XXX-XXXX
A11: 1 | B11: 循環器内科 | C11: 〇 | D11: じゅんない | E11: じゅんかん | F11: じゅんかんき | H11: =IFERROR(VLOOKUP($B11,'発話マスタ'!$A:$K,H$8,0),"") | I11: =IFERROR(VLOOKUP($B11,'発話マスタ'!$A:$K,I$8,0),"") | J11: =IFERROR(VLOOKUP($B11,'発話マスタ'!$A:$K,J$8,0),"") | K11: =IFERROR(VLOOKUP($B11,'発話マスタ'!$A:$K,K$8,0),"") | L11: =IFERROR(VLOOKUP($B11,'発話マスタ'!$A:$K,L$8,0),"") | M11: =IFERROR(VLOOKUP($B11,'発話マスタ'!$A:$K,M$8,0),"")
A12: 2 | B12: 呼吸器内科 | C12: 〇 | D12: こきゅうき | E12: こない | F12: こきゅう | H12: =IFERROR(VLOOKUP($B12,'発話マスタ'!$A:$K,H$8,0),"") | I12: =IFERROR(VLOOKUP($B12,'発話マスタ'!$A:$K,I$8,0),"") | J12: =IFERROR(VLOOKUP($B12,'発話マスタ'!$A:$K,J$8,0),"") | K12: =IFERROR(VLOOKUP($B12,'発話マスタ'!$A:$K,K$8,0),"") | L12: =IFERROR(VLOOKUP($B12,'発話マスタ'!$A:$K,L$8,0),"") | M12: =IFERROR(VLOOKUP($B12,'発話マスタ'!$A:$K,M$8,0),"")
A13: 3 | B13: 消化器内科 | C13: 〇 | D13: しょうかき | E13: しょうない | F13: いちょうか | G13: しょうかきびょう | H13: =IFERROR(VLOOKUP($B13,'発話マスタ'!$A:$K,H$8,0),"") | I13: =IFERROR(VLOOKUP($B13,'発話マスタ'!$A:$K,I$8,0),"") | J13: =IFERROR(VLOOKUP($B13,'発話マスタ'!$A:$K,J$8,0),"") | K13: =IFERROR(VLOOKUP($B13,'発話マスタ'!$A:$K,K$8,0),"") | L13: =IFERROR(VLOOKUP($B13,'発話マスタ'!$A:$K,L$8,0),"") | M13: =IFERROR(VLOOKUP($B13,'発話マスタ'!$A:$K,M$8,0),"")
A14: 4 | B14: 脳神経内科 | C14: 〇 | D14: のうない | E14: のうしん | F14: しんけい | H14: =IFERROR(VLOOKUP($B14,'発話マスタ'!$A:$K,H$8,0),"") | I14: =IFERROR(VLOOKUP($B14,'発話マスタ'!$A:$K,I$8,0),"") | J14: =IFERROR(VLOOKUP($B14,'発話マスタ'!$A:$K,J$8,0),"") | K14: =IFERROR(VLOOKUP($B14,'発話マスタ'!$A:$K,K$8,0),"") | L14: =IFERROR(VLOOKUP($B14,'発話マスタ'!$A:$K,L$8,0),"") | M14: =IFERROR(VLOOKUP($B14,'発話マスタ'!$A:$K,M$8,0),"")
A15: 5 | B15: 内分泌代謝内科 | C15: 〇 | D15: ないぶん | E15: ないぶんぴ | F15: ないぶんぴつ | G15: とうにょうびょう | H15: とうにょう | I15: たいしゃ | J15: =IFERROR(VLOOKUP($B15,'発話マスタ'!$A:$K,J$8,0),"") | K15: =IFERROR(VLOOKUP($B15,'発話マスタ'!$A:$K,K$8,0),"") | L15: =IFERROR(VLOOKUP($B15,'発話マスタ'!$A:$K,L$8,0),"") | M15: =IFERROR(VLOOKUP($B15,'発話マスタ'!$A:$K,M$8,0),"")
A16: 6 | B16: 腎臓内科 | C16: 〇 | D16: じんない | E16: じんぞう | F16: じん | G16: =IFERROR(VLOOKUP($B16,'発話マスタ'!$A:$K,G$8,0),"") | H16: =IFERROR(VLOOKUP($B16,'発話マスタ'!$A:$K,H$8,0),"") | I16: =IFERROR(VLOOKUP($B16,'発話マスタ'!$A:$K,I$8,0),"") | J16: =IFERROR(VLOOKUP($B16,'発話マスタ'!$A:$K,J$8,0),"") | K16: =IFERROR(VLOOKUP($B16,'発話マスタ'!$A:$K,K$8,0),"") | L16: =IFERROR(VLOOKUP($B16,'発話マスタ'!$A:$K,L$8,0),"") | M16: =IFERROR(VLOOKUP($B16,'発話マスタ'!$A:$K,M$8,0),"")
A17: 7 | B17: 血液内科 | C17: 〇 | D17: けつない | E17: けつえき | F17: =IFERROR(VLOOKUP($B17,'発話マスタ'!$A:$K,F$8,0),"") | G17: =IFERROR(VLOOKUP($B17,'発話マスタ'!$A:$K,G$8,0),"") | H17: =IFERROR(VLOOKUP($B17,'発話マスタ'!$A:$K,H$8,0),"") | I17: =IFERROR(VLOOKUP($B17,'発話マスタ'!$A:$K,I$8,0),"") | J17: =IFERROR(VLOOKUP($B17,'発話マスタ'!$A:$K,J$8,0),"") | K17: =IFERROR(VLOOKUP($B17,'発話マスタ'!$A:$K,K$8,0),"") | L17: =IFERROR(VLOOKUP($B17,'発話マスタ'!$A:$K,L$8,0),"") | M17: =IFERROR(VLOOKUP($B17,'発話マスタ'!$A:$K,M$8,0),"")
A18: 8 | B18: 精神科 | C18: 〇 | D18: せいしん | E18: =IFERROR(VLOOKUP($B18,'発話マスタ'!$A:$K,E$8,0),"") | F18: =IFERROR(VLOOKUP($B18,'発話マスタ'!$A:$K,F$8,0),"") | G18: =IFERROR(VLOOKUP($B18,'発話マスタ'!$A:$K,G$8,0),"") | H18: =IFERROR(VLOOKUP($B18,'発話マスタ'!$A:$K,H$8,0),"") | I18: =IFERROR(VLOOKUP($B18,'発話マスタ'!$A:$K,I$8,0),"") | J18: =IFERROR(VLOOKUP($B18,'発話マスタ'!$A:$K,J$8,0),"") | K18: =IFERROR(VLOOKUP($B18,'発話マスタ'!$A:$K,K$8,0),"") | L18: =IFERROR(VLOOKUP($B18,'発話マスタ'!$A:$K,L$8,0),"") | M18: =IFERROR(VLOOKUP($B18,'発話マスタ'!$A:$K,M$8,0),"")
A19: 9 | B19: 緩和ケア内科 | C19: 〇 | D19: かんわ | E19: かんわけあ | F19: =IFERROR(VLOOKUP($B19,'発話マスタ'!$A:$K,F$8,0),"") | G19: =IFERROR(VLOOKUP($B19,'発話マスタ'!$A:$K,G$8,0),"") | H19: =IFERROR(VLOOKUP($B19,'発話マスタ'!$A:$K,H$8,0),"") | I19: =IFERROR(VLOOKUP($B19,'発話マスタ'!$A:$K,I$8,0),"") | J19: =IFERROR(VLOOKUP($B19,'発話マスタ'!$A:$K,J$8,0),"") | K19: =IFERROR(VLOOKUP($B19,'発話マスタ'!$A:$K,K$8,0),"") | L19: =IFERROR(VLOOKUP($B19,'発話マスタ'!$A:$K,L$8,0),"") | M19: =IFERROR(VLOOKUP($B19,'発話マスタ'!$A:$K,M$8,0),"")
A20: 10 | B20: 小児科 | C20: 〇 | D20: しょうに | E20: =IFERROR(VLOOKUP($B20,'発話マスタ'!$A:$K,E$8,0),"") | F20: =IFERROR(VLOOKUP($B20,'発話マスタ'!$A:$K,F$8,0),"") | G20: =IFERROR(VLOOKUP($B20,'発話マスタ'!$A:$K,G$8,0),"") | H20: =IFERROR(VLOOKUP($B20,'発話マスタ'!$A:$K,H$8,0),"") | I20: =IFERROR(VLOOKUP($B20,'発話マスタ'!$A:$K,I$8,0),"") | J20: =IFERROR(VLOOKUP($B20,'発話マスタ'!$A:$K,J$8,0),"") | K20: =IFERROR(VLOOKUP($B20,'発話マスタ'!$A:$K,K$8,0),"") | L20: =IFERROR(VLOOKUP($B20,'発話マスタ'!$A:$K,L$8,0),"") | M20: =IFERROR(VLOOKUP($B20,'発話マスタ'!$A:$K,M$8,0),"")
A21: 11 | B21: リハビリテーション科 | C21: 〇 | D21: りは | E21: りはびり | F21: りはびりてーしょん | G21: りはか | H21: =IFERROR(VLOOKUP($B21,'発話マスタ'!$A:$K,H$8,0),"") | I21: =IFERROR(VLOOKUP($B21,'発話マスタ'!$A:$K,I$8,0),"") | J21: =IFERROR(VLOOKUP($B21,'発話マスタ'!$A:$K,J$8,0),"") | K21: =IFERROR(VLOOKUP($B21,'発話マスタ'!$A:$K,K$8,0),"") | L21: =IFERROR(VLOOKUP($B21,'発話マスタ'!$A:$K,L$8,0),"") | M21: =IFERROR(VLOOKUP($B21,'発話マスタ'!$A:$K,M$8,0),"")
A22: 12 | B22: 感染症内科 | C22: 〇 | D22: かんせんしょう | E22: かんせん | F22: =IFERROR(VLOOKUP($B22,'発話マスタ'!$A:$K,F$8,0),"") | G22: =IFERROR(VLOOKUP($B22,'発話マスタ'!$A:$K,G$8,0),"") | H22: =IFERROR(VLOOKUP($B22,'発話マスタ'!$A:$K,H$8,0),"") | I22: =IFERROR(VLOOKUP($B22,'発話マスタ'!$A:$K,I$8,0),"") | J22: =IFERROR(VLOOKUP($B22,'発話マスタ'!$A:$K,J$8,0),"") | K22: =IFERROR(VLOOKUP($B22,'発話マスタ'!$A:$K,K$8,0),"") | L22: =IFERROR(VLOOKUP($B22,'発話マスタ'!$A:$K,L$8,0),"") | M22: =IFERROR(VLOOKUP($B22,'発話マスタ'!$A:$K,M$8,0),"")
A23: 13 | B23: 輸血科 | C23: 〇 | D23: ゆけつ | E23: =IFERROR(VLOOKUP($B23,'発話マスタ'!$A:$K,E$8,0),"") | F23: =IFERROR(VLOOKUP($B23,'発話マスタ'!$A:$K,F$8,0),"") | G23: =IFERROR(VLOOKUP($B23,'発話マスタ'!$A:$K,G$8,0),"") | H23: =IFERROR(VLOOKUP($B23,'発話マスタ'!$A:$K,H$8,0),"") | I23: =IFERROR(VLOOKUP($B23,'発話マスタ'!$A:$K,I$8,0),"") | J23: =IFERROR(VLOOKUP($B23,'発話マスタ'!$A:$K,J$8,0),"") | K23: =IFERROR(VLOOKUP($B23,'発話マスタ'!$A:$K,K$8,0),"") | L23: =IFERROR(VLOOKUP($B23,'発話マスタ'!$A:$K,L$8,0),"") | M23: =IFERROR(VLOOKUP($B23,'発話マスタ'!$A:$K,M$8,0),"")
A24: 14 | B24: 外科 | C24: 〇 | D24: =IFERROR(VLOOKUP($B24,'発話マスタ'!$A:$K,D$8,0),"") | E24: =IFERROR(VLOOKUP($B24,'発話マスタ'!$A:$K,E$8,0),"") | F24: =IFERROR(VLOOKUP($B24,'発話マスタ'!$A:$K,F$8,0),"") | G24: =IFERROR(VLOOKUP($B24,'発話マスタ'!$A:$K,G$8,0),"") | H24: =IFERROR(VLOOKUP($B24,'発話マスタ'!$A:$K,H$8,0),"") | I24: =IFERROR(VLOOKUP($B24,'発話マスタ'!$A:$K,I$8,0),"") | J24: =IFERROR(VLOOKUP($B24,'発話マスタ'!$A:$K,J$8,0),"") | K24: =IFERROR(VLOOKUP($B24,'発話マスタ'!$A:$K,K$8,0),"") | ... M24: =IFERROR(VLOOKUP($B24,'発話マスタ'!$A:$K,M$8,0),"")
A25: 15 | B25: 乳腺外科 | C25: 〇 | D25: にゅうげ | E25: にゅうせん | F25: =IFERROR(VLOOKUP($B25,'発話マスタ'!$A:$K,F$8,0),"") | G25: =IFERROR(VLOOKUP($B25,'発話マスタ'!$A:$K,G$8,0),"") | H25: =IFERROR(VLOOKUP($B25,'発話マスタ'!$A:$K,H$8,0),"") | I25: =IFERROR(VLOOKUP($B25,'発話マスタ'!$A:$K,I$8,0),"") | J25: =IFERROR(VLOOKUP($B25,'発話マスタ'!$A:$K,J$8,0),"") | K25: =IFERROR(VLOOKUP($B25,'発話マスタ'!$A:$K,K$8,0),"") | L25: =IFERROR(VLOOKUP($B25,'発話マスタ'!$A:$K,L$8,0),"") | M25: =IFERROR(VLOOKUP($B25,'発話マスタ'!$A:$K,M$8,0),"")
A26: 16 | B26: 整形外科 | C26: 〇 | D26: せいけい | E26: =IFERROR(VLOOKUP($B26,'発話マスタ'!$A:$K,E$8,0),"") | F26: =IFERROR(VLOOKUP($B26,'発話マスタ'!$A:$K,F$8,0),"") | G26: =IFERROR(VLOOKUP($B26,'発話マスタ'!$A:$K,G$8,0),"") | H26: =IFERROR(VLOOKUP($B26,'発話マスタ'!$A:$K,H$8,0),"") | I26: =IFERROR(VLOOKUP($B26,'発話マスタ'!$A:$K,I$8,0),"") | J26: =IFERROR(VLOOKUP($B26,'発話マスタ'!$A:$K,J$8,0),"") | K26: =IFERROR(VLOOKUP($B26,'発話マスタ'!$A:$K,K$8,0),"") | L26: =IFERROR(VLOOKUP($B26,'発話マスタ'!$A:$K,L$8,0),"") | M26: =IFERROR(VLOOKUP($B26,'発話マスタ'!$A:$K,M$8,0),"")
A27: 17 | B27: 脳神経外科 | C27: 〇 | D27: のうげ | E27: のうしんけい | F27: =IFERROR(VLOOKUP($B27,'発話マスタ'!$A:$K,F$8,0),"") | G27: =IFERROR(VLOOKUP($B27,'発話マスタ'!$A:$K,G$8,0),"") | H27: =IFERROR(VLOOKUP($B27,'発話マスタ'!$A:$K,H$8,0),"") | I27: =IFERROR(VLOOKUP($B27,'発話マスタ'!$A:$K,I$8,0),"") | J27: =IFERROR(VLOOKUP($B27,'発話マスタ'!$A:$K,J$8,0),"") | K27: =IFERROR(VLOOKUP($B27,'発話マスタ'!$A:$K,K$8,0),"") | L27: =IFERROR(VLOOKUP($B27,'発話マスタ'!$A:$K,L$8,0),"") | M27: =IFERROR(VLOOKUP($B27,'発話マスタ'!$A:$K,M$8,0),"")
A28: 18 | B28: 形成外科 | C28: 〇 | D28: けいせい | E28: =IFERROR(VLOOKUP($B28,'発話マスタ'!$A:$K,E$8,0),"") | F28: =IFERROR(VLOOKUP($B28,'発話マスタ'!$A:$K,F$8,0),"") | G28: =IFERROR(VLOOKUP($B28,'発話マスタ'!$A:$K,G$8,0),"") | H28: =IFERROR(VLOOKUP($B28,'発話マスタ'!$A:$K,H$8,0),"") | I28: =IFERROR(VLOOKUP($B28,'発話マスタ'!$A:$K,I$8,0),"") | J28: =IFERROR(VLOOKUP($B28,'発話マスタ'!$A:$K,J$8,0),"") | K28: =IFERROR(VLOOKUP($B28,'発話マスタ'!$A:$K,K$8,0),"") | L28: =IFERROR(VLOOKUP($B28,'発話マスタ'!$A:$K,L$8,0),"") | M28: =IFERROR(VLOOKUP($B28,'発話マスタ'!$A:$K,M$8,0),"")
A29: 19 | B29: 皮膚科 | C29: 〇 | D29: ひふ | E29: =IFERROR(VLOOKUP($B29,'発話マスタ'!$A:$K,E$8,0),"") | F29: =IFERROR(VLOOKUP($B29,'発話マスタ'!$A:$K,F$8,0),"") | G29: =IFERROR(VLOOKUP($B29,'発話マスタ'!$A:$K,G$8,0),"") | H29: =IFERROR(VLOOKUP($B29,'発話マスタ'!$A:$K,H$8,0),"") | I29: =IFERROR(VLOOKUP($B29,'発話マスタ'!$A:$K,I$8,0),"") | J29: =IFERROR(VLOOKUP($B29,'発話マスタ'!$A:$K,J$8,0),"") | K29: =IFERROR(VLOOKUP($B29,'発話マスタ'!$A:$K,K$8,0),"") | L29: =IFERROR(VLOOKUP($B29,'発話マスタ'!$A:$K,L$8,0),"") | M29: =IFERROR(VLOOKUP($B29,'発話マスタ'!$A:$K,M$8,0),"")
A30: 20 | B30: 泌尿器科 | C30: 〇 | D30: ひにょうき | E30: =IFERROR(VLOOKUP($B30,'発話マスタ'!$A:$K,E$8,0),"") | F30: =IFERROR(VLOOKUP($B30,'発話マスタ'!$A:$K,F$8,0),"") | G30: =IFERROR(VLOOKUP($B30,'発話マスタ'!$A:$K,G$8,0),"") | H30: =IFERROR(VLOOKUP($B30,'発話マスタ'!$A:$K,H$8,0),"") | I30: =IFERROR(VLOOKUP($B30,'発話マスタ'!$A:$K,I$8,0),"") | J30: =IFERROR(VLOOKUP($B30,'発話マスタ'!$A:$K,J$8,0),"") | K30: =IFERROR(VLOOKUP($B30,'発話マスタ'!$A:$K,K$8,0),"") | L30: =IFERROR(VLOOKUP($B30,'発話マスタ'!$A:$K,L$8,0),"") | M30: =IFERROR(VLOOKUP($B30,'発話マスタ'!$A:$K,M$8,0),"")
A31: 21 | B31: 産婦⼈科 | C31: 〇 | D31: さんか | E31: ふじんか | F31: さんぷ | G31: さんふ | H31: =IFERROR(VLOOKUP($B31,'発話マスタ'!$A:$K,H$8,0),"") | I31: =IFERROR(VLOOKUP($B31,'発話マスタ'!$A:$K,I$8,0),"") | J31: =IFERROR(VLOOKUP($B31,'発話マスタ'!$A:$K,J$8,0),"") | K31: =IFERROR(VLOOKUP($B31,'発話マスタ'!$A:$K,K$8,0),"") | L31: =IFERROR(VLOOKUP($B31,'発話マスタ'!$A:$K,L$8,0),"") | M31: =IFERROR(VLOOKUP($B31,'発話マスタ'!$A:$K,M$8,0),"")
A32: 22 | B32: 眼科 | C32: 〇 | D32: め | E32: =IFERROR(VLOOKUP($B32,'発話マスタ'!$A:$K,E$8,0),"") | F32: =IFERROR(VLOOKUP($B32,'発話マスタ'!$A:$K,F$8,0),"") | G32: =IFERROR(VLOOKUP($B32,'発話マスタ'!$A:$K,G$8,0),"") | H32: =IFERROR(VLOOKUP($B32,'発話マスタ'!$A:$K,H$8,0),"") | I32: =IFERROR(VLOOKUP($B32,'発話マスタ'!$A:$K,I$8,0),"") | J32: =IFERROR(VLOOKUP($B32,'発話マスタ'!$A:$K,J$8,0),"") | K32: =IFERROR(VLOOKUP($B32,'発話マスタ'!$A:$K,K$8,0),"") | L32: =IFERROR(VLOOKUP($B32,'発話マスタ'!$A:$K,L$8,0),"") | M32: =IFERROR(VLOOKUP($B32,'発話マスタ'!$A:$K,M$8,0),"")
A33: 23 | B33: ⽿⿐咽喉科 | C33: 〇 | D33: じびか | E33: じび | F33: =IFERROR(VLOOKUP($B33,'発話マスタ'!$A:$K,F$8,0),"") | G33: =IFERROR(VLOOKUP($B33,'発話マスタ'!$A:$K,G$8,0),"") | H33: =IFERROR(VLOOKUP($B33,'発話マスタ'!$A:$K,H$8,0),"") | I33: =IFERROR(VLOOKUP($B33,'発話マスタ'!$A:$K,I$8,0),"") | J33: =IFERROR(VLOOKUP($B33,'発話マスタ'!$A:$K,J$8,0),"") | K33: =IFERROR(VLOOKUP($B33,'発話マスタ'!$A:$K,K$8,0),"") | L33: =IFERROR(VLOOKUP($B33,'発話マスタ'!$A:$K,L$8,0),"") | M33: =IFERROR(VLOOKUP($B33,'発話マスタ'!$A:$K,M$8,0),"")
A34: 24 | B34: ⻭科⼝腔外科 | C34: 〇 | D34: しか | E34: しかこうくう | F34: こうくうげか | G34: こうくう | H34: =IFERROR(VLOOKUP($B34,'発話マスタ'!$A:$K,H$8,0),"") | I34: =IFERROR(VLOOKUP($B34,'発話マスタ'!$A:$K,I$8,0),"") | J34: =IFERROR(VLOOKUP($B34,'発話マスタ'!$A:$K,J$8,0),"") | K34: =IFERROR(VLOOKUP($B34,'発話マスタ'!$A:$K,K$8,0),"") | L34: =IFERROR(VLOOKUP($B34,'発話マスタ'!$A:$K,L$8,0),"") | M34: =IFERROR(VLOOKUP($B34,'発話マスタ'!$A:$K,M$8,0),"")
A35: 25 | B35: 麻酔科 | C35: 〇 | D35: ますい | E35: =IFERROR(VLOOKUP($B35,'発話マスタ'!$A:$K,E$8,0),"") | F35: =IFERROR(VLOOKUP($B35,'発話マスタ'!$A:$K,F$8,0),"") | G35: =IFERROR(VLOOKUP($B35,'発話マスタ'!$A:$K,G$8,0),"") | H35: =IFERROR(VLOOKUP($B35,'発話マスタ'!$A:$K,H$8,0),"") | I35: =IFERROR(VLOOKUP($B35,'発話マスタ'!$A:$K,I$8,0),"") | J35: =IFERROR(VLOOKUP($B35,'発話マスタ'!$A:$K,J$8,0),"") | K35: =IFERROR(VLOOKUP($B35,'発話マスタ'!$A:$K,K$8,0),"") | L35: =IFERROR(VLOOKUP($B35,'発話マスタ'!$A:$K,L$8,0),"") | M35: =IFERROR(VLOOKUP($B35,'発話マスタ'!$A:$K,M$8,0),"")
A36: 26 | B36: 救急科 | C36: × | D36: きゅうきゅう | E36: =IFERROR(VLOOKUP($B36,'発話マスタ'!$A:$K,E$8,0),"") | F36: =IFERROR(VLOOKUP($B36,'発話マスタ'!$A:$K,F$8,0),"") | G36: =IFERROR(VLOOKUP($B36,'発話マスタ'!$A:$K,G$8,0),"") | H36: =IFERROR(VLOOKUP($B36,'発話マスタ'!$A:$K,H$8,0),"") | I36: =IFERROR(VLOOKUP($B36,'発話マスタ'!$A:$K,I$8,0),"") | J36: =IFERROR(VLOOKUP($B36,'発話マスタ'!$A:$K,J$8,0),"") | K36: =IFERROR(VLOOKUP($B36,'発話マスタ'!$A:$K,K$8,0),"") | L36: =IFERROR(VLOOKUP($B36,'発話マスタ'!$A:$K,L$8,0),"") | M36: =IFERROR(VLOOKUP($B36,'発話マスタ'!$A:$K,M$8,0),"")
A37: 27 | B37: 内科 | C37: 〇 | D37: ないか | E37: =IFERROR(VLOOKUP($B37,'発話マスタ'!$A:$K,E$8,0),"") | F37: =IFERROR(VLOOKUP($B37,'発話マスタ'!$A:$K,F$8,0),"") | G37: =IFERROR(VLOOKUP($B37,'発話マスタ'!$A:$K,G$8,0),"") | H37: =IFERROR(VLOOKUP($B37,'発話マスタ'!$A:$K,H$8,0),"") | I37: =IFERROR(VLOOKUP($B37,'発話マスタ'!$A:$K,I$8,0),"") | J37: =IFERROR(VLOOKUP($B37,'発話マスタ'!$A:$K,J$8,0),"") | K37: =IFERROR(VLOOKUP($B37,'発話マスタ'!$A:$K,K$8,0),"") | L37: =IFERROR(VLOOKUP($B37,'発話マスタ'!$A:$K,L$8,0),"") | M37: =IFERROR(VLOOKUP($B37,'発話マスタ'!$A:$K,M$8,0),"")
A38: 28 | D38: =IFERROR(VLOOKUP($B38,'発話マスタ'!$A:$K,D$8,0),"") | E38: =IFERROR(VLOOKUP($B38,'発話マスタ'!$A:$K,E$8,0),"") | F38: =IFERROR(VLOOKUP($B38,'発話マスタ'!$A:$K,F$8,0),"") | G38: =IFERROR(VLOOKUP($B38,'発話マスタ'!$A:$K,G$8,0),"") | H38: =IFERROR(VLOOKUP($B38,'発話マスタ'!$A:$K,H$8,0),"") | I38: =IFERROR(VLOOKUP($B38,'発話マスタ'!$A:$K,I$8,0),"") | J38: =IFERROR(VLOOKUP($B38,'発話マスタ'!$A:$K,J$8,0),"") | K38: =IFERROR(VLOOKUP($B38,'発話マスタ'!$A:$K,K$8,0),"") | ... M38: =IFERROR(VLOOKUP($B38,'発話マスタ'!$A:$K,M$8,0),"")
A39: 29 | D39: =IFERROR(VLOOKUP($B39,'発話マスタ'!$A:$K,D$8,0),"") | E39: =IFERROR(VLOOKUP($B39,'発話マスタ'!$A:$K,E$8,0),"") | F39: =IFERROR(VLOOKUP($B39,'発話マスタ'!$A:$K,F$8,0),"") | G39: =IFERROR(VLOOKUP($B39,'発話マスタ'!$A:$K,G$8,0),"") | H39: =IFERROR(VLOOKUP($B39,'発話マスタ'!$A:$K,H$8,0),"") | I39: =IFERROR(VLOOKUP($B39,'発話マスタ'!$A:$K,I$8,0),"") | J39: =IFERROR(VLOOKUP($B39,'発話マスタ'!$A:$K,J$8,0),"") | K39: =IFERROR(VLOOKUP($B39,'発話マスタ'!$A:$K,K$8,0),"") | ... M39: =IFERROR(VLOOKUP($B39,'発話マスタ'!$A:$K,M$8,0),"")
A40: 30 | D40: =IFERROR(VLOOKUP($B40,'発話マスタ'!$A:$K,D$8,0),"") | E40: =IFERROR(VLOOKUP($B40,'発話マスタ'!$A:$K,E$8,0),"") | F40: =IFERROR(VLOOKUP($B40,'発話マスタ'!$A:$K,F$8,0),"") | G40: =IFERROR(VLOOKUP($B40,'発話マスタ'!$A:$K,G$8,0),"") | H40: =IFERROR(VLOOKUP($B40,'発話マスタ'!$A:$K,H$8,0),"") | I40: =IFERROR(VLOOKUP($B40,'発話マスタ'!$A:$K,I$8,0),"") | J40: =IFERROR(VLOOKUP($B40,'発話マスタ'!$A:$K,J$8,0),"") | K40: =IFERROR(VLOOKUP($B40,'発話マスタ'!$A:$K,K$8,0),"") | ... M40: =IFERROR(VLOOKUP($B40,'発話マスタ'!$A:$K,M$8,0),"")
A41: 31 | D41: =IFERROR(VLOOKUP($B41,'発話マスタ'!$A:$K,D$8,0),"") | E41: =IFERROR(VLOOKUP($B41,'発話マスタ'!$A:$K,E$8,0),"") | F41: =IFERROR(VLOOKUP($B41,'発話マスタ'!$A:$K,F$8,0),"") | G41: =IFERROR(VLOOKUP($B41,'発話マスタ'!$A:$K,G$8,0),"") | H41: =IFERROR(VLOOKUP($B41,'発話マスタ'!$A:$K,H$8,0),"") | I41: =IFERROR(VLOOKUP($B41,'発話マスタ'!$A:$K,I$8,0),"") | J41: =IFERROR(VLOOKUP($B41,'発話マスタ'!$A:$K,J$8,0),"") | K41: =IFERROR(VLOOKUP($B41,'発話マスタ'!$A:$K,K$8,0),"") | ... M41: =IFERROR(VLOOKUP($B41,'発話マスタ'!$A:$K,M$8,0),"")
...

Sheet ②（選択）健診ヒアリングシート 
A1: 健診ヒアリングシート | M1: ↑
M2: 類義語足りなければプラスを押す
A3: 対応依頼事項
A4: B列【登録診療科名】・・・貴院HPに記載のある診療科名を記載しております。Dr.JOY管理画面へ表示させる診療科名となるため、ご確認をお願いします。表示名を変える場合は、ご修正ください。
A5: D列以降【類義語】・・・B列の診療科名に対して、患者さんが発話される可能性のある別称を記載しております。類義語の追加がございましたら、他の診療科と重複しないよう追記をお願いいたします。
A6: C列・AA列・・・AI電話で内容を受け付けない診療科や、転送をする診療科があればC列に記載ください。また、転送の場合はAA列に転送先番号を記載ください。
D8: 2 | E8: 3 | F8: 4 | G8: 5 | H8: 6 | I8: 7 | J8: 8 | K8: 9 | L8: 10 | M8: 11
A9: No. | B9: 登録健診名 (Dr.JOY管理画面へ表示する名称) | C9: AI電話対応可否 (〇可 / ×不可 / △転送) | D9: 類義語 | E9: 類義語 | F9: 類義語 | G9: 類義語 | H9: 類義語 | I9: 類義語 | J9: 類義語 | K9: 類義語 | L9: 類義語 | M9: 類義語 | N9: 類義語 | O9: 類義語 | P9: 類義語 | Q9: 類義語 | R9: 類義語 | S9: 類義語 | T9: 類義語 | U9: 類義語 | V9: 類義語 | W9: 類義語 | X9: 類義語 | Y9: 類義語 | Z9: 類義語 | AA9: 備考 (転送先電話番号)
A10: 例 | B10: 人間ドック | C10: 〇 | D10: にんげんどっく | E10: どっく | AA10: 0XX-XXX-XXXX
A11: 1 | D11: =IFERROR(VLOOKUP($B11,'発話マスタ'!$A:$K,D$8,0),"") | E11: =IFERROR(VLOOKUP($B11,'発話マスタ'!$A:$K,E$8,0),"") | F11: =IFERROR(VLOOKUP($B11,'発話マスタ'!$A:$K,F$8,0),"") | G11: =IFERROR(VLOOKUP($B11,'発話マスタ'!$A:$K,G$8,0),"") | H11: =IFERROR(VLOOKUP($B11,'発話マスタ'!$A:$K,H$8,0),"") | I11: =IFERROR(VLOOKUP($B11,'発話マスタ'!$A:$K,I$8,0),"") | J11: =IFERROR(VLOOKUP($B11,'発話マスタ'!$A:$K,J$8,0),"") | K11: =IFERROR(VLOOKUP($B11,'発話マスタ'!$A:$K,K$8,0),"") | ... M11: =IFERROR(VLOOKUP($B11,'発話マスタ'!$A:$K,M$8,0),"")
A12: 2 | D12: =IFERROR(VLOOKUP($B12,'発話マスタ'!$A:$K,D$8,0),"") | E12: =IFERROR(VLOOKUP($B12,'発話マスタ'!$A:$K,E$8,0),"") | F12: =IFERROR(VLOOKUP($B12,'発話マスタ'!$A:$K,F$8,0),"") | G12: =IFERROR(VLOOKUP($B12,'発話マスタ'!$A:$K,G$8,0),"") | H12: =IFERROR(VLOOKUP($B12,'発話マスタ'!$A:$K,H$8,0),"") | I12: =IFERROR(VLOOKUP($B12,'発話マスタ'!$A:$K,I$8,0),"") | J12: =IFERROR(VLOOKUP($B12,'発話マスタ'!$A:$K,J$8,0),"") | K12: =IFERROR(VLOOKUP($B12,'発話マスタ'!$A:$K,K$8,0),"") | ... M12: =IFERROR(VLOOKUP($B12,'発話マスタ'!$A:$K,M$8,0),"")
A13: 3 | D13: =IFERROR(VLOOKUP($B13,'発話マスタ'!$A:$K,D$8,0),"") | E13: =IFERROR(VLOOKUP($B13,'発話マスタ'!$A:$K,E$8,0),"") | F13: =IFERROR(VLOOKUP($B13,'発話マスタ'!$A:$K,F$8,0),"") | G13: =IFERROR(VLOOKUP($B13,'発話マスタ'!$A:$K,G$8,0),"") | H13: =IFERROR(VLOOKUP($B13,'発話マスタ'!$A:$K,H$8,0),"") | I13: =IFERROR(VLOOKUP($B13,'発話マスタ'!$A:$K,I$8,0),"") | J13: =IFERROR(VLOOKUP($B13,'発話マスタ'!$A:$K,J$8,0),"") | K13: =IFERROR(VLOOKUP($B13,'発話マスタ'!$A:$K,K$8,0),"") | ... M13: =IFERROR(VLOOKUP($B13,'発話マスタ'!$A:$K,M$8,0),"")
A14: 4 | D14: =IFERROR(VLOOKUP($B14,'発話マスタ'!$A:$K,D$8,0),"") | E14: =IFERROR(VLOOKUP($B14,'発話マスタ'!$A:$K,E$8,0),"") | F14: =IFERROR(VLOOKUP($B14,'発話マスタ'!$A:$K,F$8,0),"") | G14: =IFERROR(VLOOKUP($B14,'発話マスタ'!$A:$K,G$8,0),"") | H14: =IFERROR(VLOOKUP($B14,'発話マスタ'!$A:$K,H$8,0),"") | I14: =IFERROR(VLOOKUP($B14,'発話マスタ'!$A:$K,I$8,0),"") | J14: =IFERROR(VLOOKUP($B14,'発話マスタ'!$A:$K,J$8,0),"") | K14: =IFERROR(VLOOKUP($B14,'発話マスタ'!$A:$K,K$8,0),"") | ... M14: =IFERROR(VLOOKUP($B14,'発話マスタ'!$A:$K,M$8,0),"")
A15: 5 | D15: =IFERROR(VLOOKUP($B15,'発話マスタ'!$A:$K,D$8,0),"") | E15: =IFERROR(VLOOKUP($B15,'発話マスタ'!$A:$K,E$8,0),"") | F15: =IFERROR(VLOOKUP($B15,'発話マスタ'!$A:$K,F$8,0),"") | G15: =IFERROR(VLOOKUP($B15,'発話マスタ'!$A:$K,G$8,0),"") | H15: =IFERROR(VLOOKUP($B15,'発話マスタ'!$A:$K,H$8,0),"") | I15: =IFERROR(VLOOKUP($B15,'発話マスタ'!$A:$K,I$8,0),"") | J15: =IFERROR(VLOOKUP($B15,'発話マスタ'!$A:$K,J$8,0),"") | K15: =IFERROR(VLOOKUP($B15,'発話マスタ'!$A:$K,K$8,0),"") | ... M15: =IFERROR(VLOOKUP($B15,'発話マスタ'!$A:$K,M$8,0),"")
A16: 6 | D16: =IFERROR(VLOOKUP($B16,'発話マスタ'!$A:$K,D$8,0),"") | E16: =IFERROR(VLOOKUP($B16,'発話マスタ'!$A:$K,E$8,0),"") | F16: =IFERROR(VLOOKUP($B16,'発話マスタ'!$A:$K,F$8,0),"") | G16: =IFERROR(VLOOKUP($B16,'発話マスタ'!$A:$K,G$8,0),"") | H16: =IFERROR(VLOOKUP($B16,'発話マスタ'!$A:$K,H$8,0),"") | I16: =IFERROR(VLOOKUP($B16,'発話マスタ'!$A:$K,I$8,0),"") | J16: =IFERROR(VLOOKUP($B16,'発話マスタ'!$A:$K,J$8,0),"") | K16: =IFERROR(VLOOKUP($B16,'発話マスタ'!$A:$K,K$8,0),"") | ... M16: =IFERROR(VLOOKUP($B16,'発話マスタ'!$A:$K,M$8,0),"")
A17: 7 | D17: =IFERROR(VLOOKUP($B17,'発話マスタ'!$A:$K,D$8,0),"") | E17: =IFERROR(VLOOKUP($B17,'発話マスタ'!$A:$K,E$8,0),"") | F17: =IFERROR(VLOOKUP($B17,'発話マスタ'!$A:$K,F$8,0),"") | G17: =IFERROR(VLOOKUP($B17,'発話マスタ'!$A:$K,G$8,0),"") | H17: =IFERROR(VLOOKUP($B17,'発話マスタ'!$A:$K,H$8,0),"") | I17: =IFERROR(VLOOKUP($B17,'発話マスタ'!$A:$K,I$8,0),"") | J17: =IFERROR(VLOOKUP($B17,'発話マスタ'!$A:$K,J$8,0),"") | K17: =IFERROR(VLOOKUP($B17,'発話マスタ'!$A:$K,K$8,0),"") | ... M17: =IFERROR(VLOOKUP($B17,'発話マスタ'!$A:$K,M$8,0),"")
A18: 8 | D18: =IFERROR(VLOOKUP($B18,'発話マスタ'!$A:$K,D$8,0),"") | E18: =IFERROR(VLOOKUP($B18,'発話マスタ'!$A:$K,E$8,0),"") | F18: =IFERROR(VLOOKUP($B18,'発話マスタ'!$A:$K,F$8,0),"") | G18: =IFERROR(VLOOKUP($B18,'発話マスタ'!$A:$K,G$8,0),"") | H18: =IFERROR(VLOOKUP($B18,'発話マスタ'!$A:$K,H$8,0),"") | I18: =IFERROR(VLOOKUP($B18,'発話マスタ'!$A:$K,I$8,0),"") | J18: =IFERROR(VLOOKUP($B18,'発話マスタ'!$A:$K,J$8,0),"") | K18: =IFERROR(VLOOKUP($B18,'発話マスタ'!$A:$K,K$8,0),"") | ... M18: =IFERROR(VLOOKUP($B18,'発話マスタ'!$A:$K,M$8,0),"")
A19: 9 | D19: =IFERROR(VLOOKUP($B19,'発話マスタ'!$A:$K,D$8,0),"") | E19: =IFERROR(VLOOKUP($B19,'発話マスタ'!$A:$K,E$8,0),"") | F19: =IFERROR(VLOOKUP($B19,'発話マスタ'!$A:$K,F$8,0),"") | G19: =IFERROR(VLOOKUP($B19,'発話マスタ'!$A:$K,G$8,0),"") | H19: =IFERROR(VLOOKUP($B19,'発話マスタ'!$A:$K,H$8,0),"") | I19: =IFERROR(VLOOKUP($B19,'発話マスタ'!$A:$K,I$8,0),"") | J19: =IFERROR(VLOOKUP($B19,'発話マスタ'!$A:$K,J$8,0),"") | K19: =IFERROR(VLOOKUP($B19,'発話マスタ'!$A:$K,K$8,0),"") | ... M19: =IFERROR(VLOOKUP($B19,'発話マスタ'!$A:$K,M$8,0),"")
A20: 10 | D20: =IFERROR(VLOOKUP($B20,'発話マスタ'!$A:$K,D$8,0),"") | E20: =IFERROR(VLOOKUP($B20,'発話マスタ'!$A:$K,E$8,0),"") | F20: =IFERROR(VLOOKUP($B20,'発話マスタ'!$A:$K,F$8,0),"") | G20: =IFERROR(VLOOKUP($B20,'発話マスタ'!$A:$K,G$8,0),"") | H20: =IFERROR(VLOOKUP($B20,'発話マスタ'!$A:$K,H$8,0),"") | I20: =IFERROR(VLOOKUP($B20,'発話マスタ'!$A:$K,I$8,0),"") | J20: =IFERROR(VLOOKUP($B20,'発話マスタ'!$A:$K,J$8,0),"") | K20: =IFERROR(VLOOKUP($B20,'発話マスタ'!$A:$K,K$8,0),"") | ... M20: =IFERROR(VLOOKUP($B20,'発話マスタ'!$A:$K,M$8,0),"")
A21: 11 | D21: =IFERROR(VLOOKUP($B21,'発話マスタ'!$A:$K,D$8,0),"") | E21: =IFERROR(VLOOKUP($B21,'発話マスタ'!$A:$K,E$8,0),"") | F21: =IFERROR(VLOOKUP($B21,'発話マスタ'!$A:$K,F$8,0),"") | G21: =IFERROR(VLOOKUP($B21,'発話マスタ'!$A:$K,G$8,0),"") | H21: =IFERROR(VLOOKUP($B21,'発話マスタ'!$A:$K,H$8,0),"") | I21: =IFERROR(VLOOKUP($B21,'発話マスタ'!$A:$K,I$8,0),"") | J21: =IFERROR(VLOOKUP($B21,'発話マスタ'!$A:$K,J$8,0),"") | K21: =IFERROR(VLOOKUP($B21,'発話マスタ'!$A:$K,K$8,0),"") | ... M21: =IFERROR(VLOOKUP($B21,'発話マスタ'!$A:$K,M$8,0),"")
A22: 12 | D22: =IFERROR(VLOOKUP($B22,'発話マスタ'!$A:$K,D$8,0),"") | E22: =IFERROR(VLOOKUP($B22,'発話マスタ'!$A:$K,E$8,0),"") | F22: =IFERROR(VLOOKUP($B22,'発話マスタ'!$A:$K,F$8,0),"") | G22: =IFERROR(VLOOKUP($B22,'発話マスタ'!$A:$K,G$8,0),"") | H22: =IFERROR(VLOOKUP($B22,'発話マスタ'!$A:$K,H$8,0),"") | I22: =IFERROR(VLOOKUP($B22,'発話マスタ'!$A:$K,I$8,0),"") | J22: =IFERROR(VLOOKUP($B22,'発話マスタ'!$A:$K,J$8,0),"") | K22: =IFERROR(VLOOKUP($B22,'発話マスタ'!$A:$K,K$8,0),"") | ... M22: =IFERROR(VLOOKUP($B22,'発話マスタ'!$A:$K,M$8,0),"")
... A60: 50 | D60: =IFERROR(VLOOKUP($B60,'発話マスタ'!$A:$K,D$8,0),"") | E60: =IFERROR(VLOOKUP($B60,'発話マスタ'!$A:$K,E$8,0),"") | F60: =IFERROR(VLOOKUP($B60,'発話マスタ'!$A:$K,F$8,0),"") | G60: =IFERROR(VLOOKUP($B60,'発話マスタ'!$A:$K,G$8,0),"") | H60: =IFERROR(VLOOKUP($B60,'発話マスタ'!$A:$K,H$8,0),"") | I60: =IFERROR(VLOOKUP($B60,'発話マスタ'!$A:$K,I$8,0),"") | J60: =IFERROR(VLOOKUP($B60,'発話マスタ'!$A:$K,J$8,0),"") | K60: =IFERROR(VLOOKUP($B60,'発話マスタ'!$A:$K,K$8,0),"") | ... M60: =IFERROR(VLOOKUP($B60,'発話マスタ'!$A:$K,M$8,0),"")

Sheet ③運用ヒアリングシート
A1: 運用ヒアリングシート
A2: 以下質問項目に対して、D列に貴院の回答をご記入ください。
A4: 項目 | B4: ヒアリング内容 | C4: 回答例 | D4: ご回答
A5: 運用全般 | B5: ■AI電話の稼働希望曜日・時間をご回答ください。 | C5: 例）(月)～(金)8時～17時 ※現在の受付時間と同じ、または＋前後1～2時間とされる施設様が多いです。24時間稼働も実績がございます。 | D5: 検討中
B6: ■AI電話の稼働開始日のご希望をご回答ください。 | C6: キックオフミーティングより、1カ月半～2カ月が目安です。 | D6: 検討中
B7: ■AI電話の使用方法をご回答ください。 | C7: 例）050番号を周知し、患者さんから直接電話を受け付ける。 例）050番号は公開せず、病院代表電話番号から転送して受け付ける。 (転送費用が別途かかります。 また、電話番号の自動取得ができない場合がございます。) | D7: 検討中
A9: シナリオ | B9: ■AI電話の利用用途をご回答ください。 | C9: 例）診療・健診・地域連携室・疑義照会 など | D9: 検討中
B10: ■AI電話で対応する用件をご回答ください。 | C10: 例）新規予約・再診予約・予約変更・キャンセル・その他問い合わせ など | D10: 検討中
B11: ■AI電話で聴取する個人情報を次の中からご選択ください。 | C11: 例）氏名・生年月日・連絡先電話番号・診察券番号。 その他ご希望がある場合は、回答欄に追記ください。 | D11: 検討中

Sheet ④よくある質問
A1: よくある質問 | E1: よくある質問サンプル
A2: 質問 | B2: 応答内容 | C2: 登録 Dr.JOY記入欄 | E2: 質問 | F2: 応答内容
A3: 診察券を紛失したのですが、どうしたらいいですか？ | B3: 初診受付で再発行いたしますので、次回来院時にお申し出ください。その際に、再発行代が110円かかりますのでご了承ください。 | E3: 診察券を紛失したのですが、どうしたらいい？ | F3: 初診受付で診察券を再発行いたします。受付でお申し出下さい。
A4: 紹介状がなくても受診できますか？ | B4: 当院は、地域医療機関との役割分担、医療連携を進めるため紹介予約制となります。事前に紹介状をご準備ください。紹介状がない場合も受診は可能ですが、診療費の他に特別の料金が発生します。 | E4: 紹介状がなくても受診できますか？ | F4: 当院はかかりつけ医を推奨しているため、紹介状をご準備ください。
A5: 最寄り駅はどこですか？ | B5: 東武東上線「大山駅」から徒歩8分、「中板橋駅」から徒歩10分です。都営三田線「板橋区役所前駅」から徒歩12分です。 | E5: 初めて受診したいのですが？ | F5: 紹介状をご準備いただき、事前の予約取得をお願いします。
A6: 駐車場はありますか？ | B6: 屋外と地下2階に一般用と障がい者用合わせて187台分あります。料金は、患者さん及びお付添の方は3時間まで100円、以降1時間毎に100円。お見舞い、ご面会の方は1時間まで100円、以降1時間ごとに200円となります。 | E6: 他の病院からの紹介状を持っていますが… | F6: 予約取得をおすすめいたします。
A7: 送迎バスはありますか？ | B7: 送迎バスはありませんので、池袋駅と赤羽駅を経由する民間のバスをご利用ください。国際興業バスの「豊島病院前」が最寄りのバス停となります。 | E7: 予約日に受診できなかった場合は？ | F7: 改めて予約をお取りください
A8: 何時から病院に入れますか？ | B8: 玄関は、平日及び土曜日8時15分に開きます。なお、受付は8時30分開始となります。 | E8: 別の診療科に初めて受診する場合？ | F8: 当院通院中でも初診扱いの場合は紹介状をご用意ください。
A9: 院内にカフェやレストランはありますか？ | B9: 1階にレストランがあります。営業時間は、平日11時から15時です。 | E9: しばらく受診していないのですが… | F9: 受診歴があっても初診扱いなら紹介状が必要になります。
A10: 院内に売店はありますか？ | B10: 1階に売店があります。営業時間は、平日7時から21時、休日8時から18時です。 | E10: セカンドオピニオンについて | F10: 別の医療機関で意見を得て、納得して治療を受けることができます。
A11: 院内にATMはありますか？ | B11: 1階にセブン銀行のATMがあり、終日利用できます。 | E11: 入院したいのですが？ | F11: 外来診察後、医師の指示により入院手続きになります。
A12: 院内で郵便を取り扱ってますか？ | B12: 1階の売店内に入院患者用のポストがあります。宅配便や切手等も売店で取り扱ってます。 | E12: 個室はありますか？ | F12: 特別個室、一般個室、2床室があり料金が異なります。
A13: 院内は禁煙ですか？ | B13: 敷地内全面禁煙です。 | E13: 病室で携帯電話を使用していいですか？ | F13: マナーモードであれば可。ただし通話はご遠慮ください。
A14: 面会時間は何時から何時までですか？ | B14: 10時から21時です。 | E14: 入院中に使えるWi-Fiはありますか？ | F14: 外来・病棟エリアで無料Wi-Fiを利用可能です。
... A33: 病院の診療時間をおしえてください。 | B33: 平日は9時から17時、土曜日は9時から12時半、日曜・祭日は休診となります。 | E33: 病院へのアクセスや道順 | F33: 住所：〒105-5517、東京都港区虎ノ門2丁目6-1、虎ノ門ヒルズステーションタワー17階
E34: 病院の営業時間・受付時間 | F34: 平日8:30～11:00、13:00～15:00。土曜・日曜・祝日は休診。
E35: タクシー乗り場 | F35: 1階車寄せ。呼び出し時は迎車料金が発生。
E36: プリペイドカード（テレビ視聴など） | F36: テレビは1枚で16時間視聴可能。
E37: 予約なしで受診できますか？ | F37: 完全予約制のため、救急以外は不可。
E38: 予約時間に遅刻した場合 | F38: 空き時間対応は可能だが、長時間待つ場合あり。
E39: 保険証を忘れた場合 | F39: 月内に必ず再来院し提示をお願いします。
E40: 面会時間は何時まで？ | F40: 9:00～16:00までに受付。17:00以降は面会不可

Sheet ⑤共有物リンク
A1: Dr.JOY⇒貴院への共有物
A2: 弊社からの制作物などの共有リンクを以下へまとめております。
A4: カテゴリ | C4: 内容 | F4: リンク
A5: AI電話番号発番資料 | C5: 貴院のAI電話番号発番に関する資料
A6: アカウントログイン情報 | C6: メールアドレスをお持ちでない方の仮passが記載
A7: KMTG・定例MTG資料 | C7: MTG当日に投影した資料一覧
A8: 周知資料 | C8: 作成希望をいただいた周知資料を格納

Sheet イントネーション
A1: 文言 | B1: よみがな | C1: イントネーション（TS）

Sheet Log
A1: 日付 | B1: 編集者 | C1: シート名 | D1: 対象セル | E1: 変更前 | F1: 変更後

Sheet 単語CSV
A1: 単語 | B1: よみがな | C1: クラス | D1: 更新日時

Sheet 発話マスタ
A1: =IFERROR(__xludf.DUMMYFUNCTION("IMPORTRANGE(""https://docs.google.com/spreadsheets/d/1yB8EoyXPqqx3RB0T7HMn-MLOhyLX9FgyVr4swT_O7Go/edit?gid=0#gid=0"",""診療科!A:K"")"),"#REF!") -> #REF! | M1: このページ内に記載のない診療科がある場合は下記シートへも診療科と発話パターンの記載をしてください
M2: 診療科発話マスタ

Sheet 変則単語
A1: =IFERROR(__xludf.DUMMYFUNCTION("IMPORTRANGE(""https://docs.google.com/spreadsheets/d/1yB8EoyXPqqx3RB0T7HMn-MLOhyLX9FgyVr4swT_O7Go/edit?gid=1749992939#gid=1749992939"",""変則単語!A:B"")"),"#REF!") -> #REF! | D1: このページ内に記載のない変則単語がある場合は下記シートへも単語と読み方の記載をしてください
D2: 診療科発話マスタ
